Workbook

Sheet OVERZICHT
A1: GEMEENTE | B1: PROVINCIE | C1: NIS-CODE | D1: INWONERS 2022 (STATBEL - OFFICIËLE STATISTIEK) | E1: INWONERS 01/01/2023 (STATBEL - OFFICIËLE STATISTIEK) | F1: INWONERS 01/01/2024 (STATBEL - OFFICIËLE STATISTIEK) | G1: INWONERS 01/01/2025 (STATBEL - OFFICIËLE STATISTIEK) | H1: AANTAL DEELWAGENS JANUARI 2022 | I1: AANTAL e-DEELWAGENS JANUARI 2022 | J1: AANTAL DEELWAGENS PER 1.000 JAN 2022 | K1: AANTAL DEELWAGENS OKTOBER 2022 | L1: AANTAL e-DEELWAGENS OKTOBER 2022 | M1: AANTAL DEELWAGENS PER 1.000 OKT 2022 | N1: AANTAL DEELWAGENS JUNI 2023 | O1: AANTAL e-DEELWAGENS JUNI 2023 | P1: AANTAL DEELWAGENS PER 1.000 JUN 2023 | Q1: AANTAL e-DEELWAGENS PER 1.000 JUN 2023 | R1: GROEI aantal deelwagens jan '22 - jun '23 | S1: GROEI aantal deelwagens per 1.000 inw jan '22 - jun '23 | T1: GROEI aantal deelwagens okt '22 - jun '23 | U1: GROEI aantal deelwagens per 1.000 inw okt '22 - jun '23 | V1: AANTAL PARTICULIERE DEELWAGENS JUN 2023 | W1: AANTAL PARTICULIERE DEELWAGENS PER 1.000 JUN 2023 | X1: AANTAL DEELWAGENS DECEMBER 2023 | Y1: AANTAL e-DEELWAGENS DECEMBER 2023 | Z1: AANTAL DEELWAGENS PER 1.000 DEC 2023 | AA1: AANTAL e-DEELWAGENS PER 1.000 DEC 2023 | AB1: AANTAL DEELWAGENS JUNI 2024 | AC1: AANTAL e-DEELWAGENS JUNI 2024 | AD1: AANTAL DEELWAGENS PER 1.000 JUN 2024 | AE1: AANTAL e-DEELWAGENS PER 1.000 JUN 2024 | AF1: AANTAL DEELWAGENS DEC 2024 | AG1: AANTAL e-DEELWAGENS DEC 2024 | AH1: AANTAL DEELWAGENS PER 1.000 DEC 2024 | AI1: AANTAL e-DEELWAGENS PER 1.000 DEC 2024 | AJ1: AANTAL DEELWAGENS JUN 2025 | AK1: AANTAL e-DEELWAGENS JUN 2025 | AL1: AANTAL DEELWAGENS PER 1.000 JUN 2025 | AM1: AANTAL e-DEELWAGENS PER 1.000 JUN 2025 | AN1: VERSCHIL AANTAL DEELWAGENS JUN 25 - JUN 24 | AO1: GROEI/DALING AANTAL DEELWAGENS JUN 25 - JUN 24 | AP1: AANTAL DEELWAGENS DEC 2025 | AQ1: AANTAL e-DEELWAGENS DEC 2025 | AR1: AANTAL DEELWAGENS PER 1.000 DEC 2025 | AS1: AANTAL e-DEELWAGENS PER 1.000 DEC 2025 | AT1: VERSCHIL AANTAL DEELWAGENS DEC 25 - DEC 24 | AU1: AANTAL DEELWAGENS NODIG IN 2030 OBV INWONERS 2024 | AV1: EXTRA BENODIGDE DEELWAGENS TEGEN 2030 (OBV DEC 2024)
A2: Antwerpen | B2: Antwerpen | C2: 11002 | D2: 530630 | E2: 538910 | F2: 544759 | G2: 562002 | H2: 896 | I2: 170 | J2: 1.6885589 | K2: 899 | L2: 161 | M2: 1.6942125 | N2: 1449 | O2: 354 | P2: 2.6887606 | Q2: 0.65688148 | R2: 553 | S2: 1.0002018 | T2: 550 | U2: 0.99454811 | V2: 92 | W2: 0.17071496 | X2: 1542 | Y2: 303 | Z2: 2.8613312 | AA2: 0.56224602 | AB2: =1646+'overzicht voor jun 25'!AA40 -> 1648 | AC2: 37 | AD2: 3.0215196 | AE2: 0.067919943 | AF2: =1477 -> 1477 | AG2: 29 | AH2: 2.7112907 | AI2: 0.05323455 | AJ2: =BattMobility!D9+cambio!D9+Claus2you!D9+CoopStroom!D9+Cozywheels!D9+Dégage!D9+Flexigo!D9+Klimaan!D9+Moovee!D9+Poppy!D9+'Mobilize Share'!D9+Stapp.in!D9 -> 1342 | AK2: =BattMobility!E9+cambio!E9+Claus2you!E9+CoopStroom!E9+Cozywheels!E9+Dégage!E9+Flexigo!E9+Klimaan!E9+Moovee!E9+Poppy!E9+'Mobilize Share'!E9+Stapp.in!E9 -> 29 | AL2: =AJ2/G2*1000 -> 2.3878919 | AM2: =AK2/G2*1000 -> 0.05160124 | AN2: =AJ2-AB2 -> -306 | AO2: =AN2/AB2 -> -0.18567961 | AP2: =BattMobility!F9+cambio!F9+Claus2you!F9+CoopStroom!F9+Cozywheels!F9+Dégage!F9+Flexigo!F9+Klimaan!F9+Moovee!F9+Poppy!F9+'Mobilize Share'!F9+Stapp.in!F9 -> 1214 | AQ2: =BattMobility!G9+cambio!G9+Claus2you!G9+CoopStroom!G9+Cozywheels!G9+Dégage!G9+Flexigo!G9+Klimaan!G9+Moovee!G9+Poppy!G9+'Mobilize Share'!G9+Stapp.in!G9 -> 32 | AR2: =AP2/G2*1000 -> 2.1601347 | AS2: =AQ2/G2*1000 -> 0.056939299 | AT2: =AP2-AF2 -> -263 | AU2: 1089.518 | AV2: -387.482
A3: Gent | B3: Oost-Vlaanderen | C3: 44021 | D3: 265086 | E3: 268122 | F3: 269597 | G3: 272657 | H3: 734 | I3: 144 | J3: 2.7689127 | K3: 884 | L3: 128 | M3: 3.3347668 | N3: 1066 | O3: 240 | P3: 3.9758021 | Q3: 0.89511491 | R3: 332 | S3: 1.2068893 | T3: 182 | U3: 0.64103523 | V3: 360 | W3: 1.3426724 | X3: 890 | Y3: 202 | Z3: 3.3193845 | AA3: 0.75338838 | AB3: 1027 | AC3: 249 | AD3: 3.8093896 | AE3: 0.92360078 | AF3: 1103 | AG3: 325 | AH3: 4.0912918 | AI3: 1.205503 | AJ3: =BattMobility!D73+cambio!D73+Claus2you!D73+CoopStroom!D73+Cozywheels!D73+Dégage!D73+Flexigo!D73+Klimaan!D73+Moovee!D73+Poppy!D73+'Mobilize Share'!D73+Stapp.in!D73 -> 1075 | AK3: =BattMobility!E73+cambio!E73+Claus2you!E73+CoopStroom!E73+Cozywheels!E73+Dégage!E73+Flexigo!E73+Klimaan!E73+Moovee!E73+Poppy!E73+'Mobilize Share'!E73+Stapp.in!E73 -> 320 | AL3: =AJ3/G3*1000 -> 3.9426826 | AM3: =AK3/G3*1000 -> 1.1736357 | AN3: =AJ3-AB3 -> 48 | AO3: =AN3/AB3 -> 0.046738072 | AP3: =BattMobility!F73+cambio!F73+Claus2you!F73+CoopStroom!F73+Cozywheels!F73+Dégage!F73+Flexigo!F73+Klimaan!F73+Moovee!F73+Poppy!F73+'Mobilize Share'!F73+Stapp.in!F73 -> 1096 | AQ3: =BattMobility!G73+cambio!G73+Claus2you!G73+CoopStroom!G73+Cozywheels!G73+Dégage!G73+Flexigo!G73+Klimaan!G73+Moovee!G73+Poppy!G73+'Mobilize Share'!G73+Stapp.in!G73 -> 305 | AR3: =AP3/G3*1000 -> 4.0197024 | AS3: =AQ3/G3*1000 -> 1.1186216 | AT3: =AP3-AF3 -> -7 | AU3: 539.194 | AV3: -563.806
A4: Leuven | B4: Vlaams-Brabant | C4: 24062 | D4: 102236 | E4: 103009 | F4: 104009 | G4: 104906 | H4: 201 | I4: 5 | J4: 1.9660394 | K4: 211 | L4: 5 | M4: 2.0638523 | N4: 218 | O4: 27 | P4: 2.1163199 | Q4: 0.26211302 | R4: 17 | S4: 0.15028057 | T4: 7 | U4: 0.05246767 | V4: 53 | W4: 0.51451815 | X4: 230 | Y4: 27 | Z4: 2.2328146 | AA4: 0.26211302 | AB4: 249 | AC4: 30 | AD4: 2.3940236 | AE4: 0.28843658 | AF4: 248 | AG4: 34 | AH4: 2.384409 | AI4: 0.32689479 | AJ4: =BattMobility!D148+cambio!D148+Claus2you!D148+CoopStroom!D148+Cozywheels!D148+Dégage!D148+Flexigo!D148+Klimaan!D148+Moovee!D148+Poppy!D148+'Mobilize Share'!D148+Stapp.in!D148 -> 266 | AK4: =BattMobility!E148+cambio!E148+Claus2you!E148+CoopStroom!E148+Cozywheels!E148+Dégage!E148+Flexigo!E148+Klimaan!E148+Moovee!E148+Poppy!E148+'Mobilize Share'!E148+Stapp.in!E148 -> 36 | AL4: =AJ4/G4*1000 -> 2.5356033 | AM4: =AK4/G4*1000 -> 0.34316436 | AN4: =AJ4-AB4 -> 17 | AO4: =AN4/AB4 -> 0.068273092 | AP4: =BattMobility!F148+cambio!F148+Claus2you!F148+CoopStroom!F148+Cozywheels!F148+Dégage!F148+Flexigo!F148+Klimaan!F148+Moovee!F148+Poppy!F148+'Mobilize Share'!F148+Stapp.in!F148 -> 274 | AQ4: =BattMobility!G148+cambio!G148+Claus2you!G148+CoopStroom!G148+Cozywheels!G148+Dégage!G148+Flexigo!G148+Klimaan!G148+Moovee!G148+Poppy!G148+'Mobilize Share'!G148+Stapp.in!G148 -> 37 | AR4: =AP4/G4*1000 -> 2.611862 | AS4: =AQ4/G4*1000 -> 0.3526967 | AT4: =AP4-AF4 -> 26 | AU4: 208.018 | AV4: -39.982
A5: Mechelen | B5: Antwerpen | C5: 12025 | D5: 86996 | E5: 88614 | F5: 89313 | G5: 89655 | H5: 159 | I5: 0 | J5: 1.8276702 | K5: 204 | L5: 4 | M5: 2.3449354 | N5: 214 | O5: 38 | P5: 2.4149683 | Q5: 0.42882614 | R5: 55 | S5: 0.58729805 | T5: 10 | U5: 0.07003289 | V5: 41 | W5: 0.46268084 | X5: 162 | Y5: 39 | Z5: 1.8281536 | AA5: 0.44011104 | AB5: 159 | AC5: 39 | AD5: 1.780256 | AE5: 0.43666655 | AF5: 160 | AG5: 44 | AH5: 1.7914525 | AI5: 0.49264945 | AJ5: =BattMobility!D171+cambio!D171+Claus2you!D171+CoopStroom!D171+Cozywheels!D171+Dégage!D171+Flexigo!D171+Klimaan!D171+Moovee!D171+Poppy!D171+'Mobilize Share'!D171+Stapp.in!D171 -> 157 | AK5: =BattMobility!E171+cambio!E171+Claus2you!E171+CoopStroom!E171+Cozywheels!E171+Dégage!E171+Flexigo!E171+Klimaan!E171+Moovee!E171+Poppy!E171+'Mobilize Share'!E171+Stapp.in!E171 -> 45 | AL5: =AJ5/G5*1000 -> 1.7511572 | AM5: =AK5/G5*1000 -> 0.50192404 | AN5: =AJ5-AB5 -> -2 | AO5: =AN5/AB5 -> -0.012578616 | AP5: =BattMobility!F171+cambio!F171+Claus2you!F171+CoopStroom!F171+Cozywheels!F171+Dégage!F171+Flexigo!F171+Klimaan!F171+Moovee!F171+Poppy!F171+'Mobilize Share'!F171+Stapp.in!F171 -> 157 | AQ5: =BattMobility!G171+cambio!G171+Claus2you!G171+CoopStroom!G171+Cozywheels!G171+Dégage!G171+Flexigo!G171+Klimaan!G171+Moovee!G171+Poppy!G171+'Mobilize Share'!G171+Stapp.in!G171 -> 52 | AR5: =AP5/G5*1000 -> 1.7511572 | AS5: =AQ5/G5*1000 -> 0.58000112 | AT5: =AP5-AF5 -> -3 | AU5: 178.626 | AV5: 18.626
A6: Brugge | B6: West-Vlaanderen | C6: 31005 | D6: 118509 | E6: 119541 | F6: 119869 | G6: 120283 | H6: 58 | I6: 10 | J6: 0.48941431 | K6: 75 | L6: 12 | M6: 0.63286333 | N6: 83 | O6: 23 | P6: 0.69432245 | Q6: 0.19240261 | R6: 25 | S6: 0.20490814 | T6: 8 | U6: 0.061459123 | V6: 28 | W6: 0.23422926 | X6: 103 | Y6: 31 | Z6: 0.86162906 | AA6: 0.25932525 | AB6: 109 | AC6: 32 | AD6: 0.90932601 | AE6: 0.2669581 | AF6: 124 | AG6: 41 | AH6: 1.0344626 | AI6: 0.34204006 | AJ6: =BattMobility!D45+cambio!D45+Claus2you!D45+CoopStroom!D45+Cozywheels!D45+Dégage!D45+Flexigo!D45+Klimaan!D45+Moovee!D45+Poppy!D45+'Mobilize Share'!D45+Stapp.in!D45 -> 128 | AK6: =BattMobility!E45+cambio!E45+Claus2you!E45+CoopStroom!E45+Cozywheels!E45+Dégage!E45+Flexigo!E45+Klimaan!E45+Moovee!E45+Poppy!E45+'Mobilize Share'!E45+Stapp.in!E45 -> 43 | AL6: =AJ6/G6*1000 -> 1.064157 | AM6: =AK6/G6*1000 -> 0.35749025 | AN6: =AJ6-AB6 -> 19 | AO6: =AN6/AB6 -> 0.17431193 | AP6: =BattMobility!F45+cambio!F45+Claus2you!F45+CoopStroom!F45+Cozywheels!F45+Dégage!F45+Flexigo!F45+Klimaan!F45+Moovee!F45+Poppy!F45+'Mobilize Share'!F45+Stapp.in!F45 -> 137 | AQ6: =BattMobility!G45+cambio!G45+Claus2you!G45+CoopStroom!G45+Cozywheels!G45+Dégage!G45+Flexigo!G45+Klimaan!G45+Moovee!G45+Poppy!G45+'Mobilize Share'!G45+Stapp.in!G45 -> 49 | AR6: =AP6/G6*1000 -> 1.1389806 | AS6: =AQ6/G6*1000 -> 0.40737261 | AT6: =AP6-AF6 -> 13 | AU6: 239.738 | AV6: 115.738
A7: Kortrijk | B7: West-Vlaanderen | C7: 34022 | D7: 77741 | E7: 78944 | F7: 80032 | G7: 80776 | H7: 27 | I7: 0 | J7: 0.34730708 | K7: 31 | L7: 0 | M7: 0.39875999 | N7: 32 | O7: 4 | P7: 0.40535063 | Q7: 0.050668829 | R7: 5 | S7: 0.058043545 | T7: 1 | U7: 0.0065906432 | V7: 15 | W7: 0.19000811 | X7: 43 | Y7: 8 | Z7: 0.54468991 | AA7: 0.10133766 | AB7: 49 | AC7: 7 | AD7: 0.6122551 | AE7: 0.087465014 | AF7: 52 | AG7: 7 | AH7: 0.6497401 | AI7: 0.087465014 | AJ7: =BattMobility!D133+cambio!D133+Claus2you!D133+CoopStroom!D133+Cozywheels!D133+Dégage!D133+Flexigo!D133+Klimaan!D133+Moovee!D133+Poppy!D133+'Mobilize Share'!D133+Stapp.in!D133 -> 54 | AK7: =BattMobility!E133+cambio!E133+Claus2you!E133+CoopStroom!E133+Cozywheels!E133+Dégage!E133+Flexigo!E133+Klimaan!E133+Moovee!E133+Poppy!E133+'Mobilize Share'!E133+Stapp.in!E133 -> 7 | AL7: =AJ7/G7*1000 -> 0.6685154 | AM7: =AK7/G7*1000 -> 0.086659404 | AN7: =AJ7-AB7 -> 5 | AO7: =AN7/AB7 -> 0.10204082 | AP7: =BattMobility!F133+cambio!F133+Claus2you!F133+CoopStroom!F133+Cozywheels!F133+Dégage!F133+Flexigo!F133+Klimaan!F133+Moovee!F133+Poppy!F133+'Mobilize Share'!F133+Stapp.in!F133 -> 55 | AQ7: =BattMobility!G133+cambio!G133+Claus2you!G133+CoopStroom!G133+Cozywheels!G133+Dégage!G133+Flexigo!G133+Klimaan!G133+Moovee!G133+Poppy!G133+'Mobilize Share'!G133+Stapp.in!G133 -> 8 | AR7: =AP7/G7*1000 -> 0.68089532 | AS7: =AQ7/G7*1000 -> 0.099039319 | AT7: =AP7-AF7 -> 3 | AU7: 160.064 | AV7: 108.064
A8: Sint-Niklaas | B8: Oost-Vlaanderen | C8: 46021 | D8: 80167 | E8: 81138 | F8: 81863 | G8: 82661 | H8: 22 | I8: 0 | J8: 0.27442713 | K8: 26 | L8: 0 | M8: 0.32432298 | N8: 26 | O8: 3 | P8: 0.32044172 | Q8: 0.036974044 | R8: 4 | S8: 0.046014583 | T8: 0 | U8: -0.0038812592 | V8: 10 | W8: 0.12324681 | X8: 43 | Y8: 4 | Z8: 0.5299613 | AA8: 0.049298726 | AB8: 50 | AC8: 6 | AD8: 0.61077654 | AE8: 0.073293185 | AF8: 50 | AG8: 6 | AH8: 0.61077654 | AI8: 0.073293185 | AJ8: =BattMobility!D229+cambio!D229+Claus2you!D229+CoopStroom!D229+Cozywheels!D229+Dégage!D229+Flexigo!D229+Klimaan!D229+Moovee!D229+Poppy!D229+'Mobilize Share'!D229+Stapp.in!D229 -> 43 | AK8: =BattMobility!E229+cambio!E229+Claus2you!E229+CoopStroom!E229+Cozywheels!E229+Dégage!E229+Flexigo!E229+Klimaan!E229+Moovee!E229+Poppy!E229+'Mobilize Share'!E229+Stapp.in!E229 -> 6 | AL8: =AJ8/G8*1000 -> 0.52019695 | AM8: =AK8/G8*1000 -> 0.072585621 | AN8: =AJ8-AB8 -> -7 | AO8: =AN8/AB8 -> -0.14 | AP8: =BattMobility!F229+cambio!F229+Claus2you!F229+CoopStroom!F229+Cozywheels!F229+Dégage!F229+Flexigo!F229+Klimaan!F229+Moovee!F229+Poppy!F229+'Mobilize Share'!F229+Stapp.in!F229 -> 55 | AQ8: =BattMobility!G229+cambio!G229+Claus2you!G229+CoopStroom!G229+Cozywheels!G229+Dégage!G229+Flexigo!G229+Klimaan!G229+Moovee!G229+Poppy!G229+'Mobilize Share'!G229+Stapp.in!G229 -> 12 | AR8: =AP8/G8*1000 -> 0.66536819 | AS8: =AQ8/G8*1000 -> 0.14517124 | AT8: =AP8-AF8 -> 5 | AU8: 163.726 | AV8: 113.726
A9: Hasselt | B9: Limburg | C9: 71072 | D9: 79524 | E9: 80351 | F9: 80828 | G9: 90249 | H9: 30 | I9: 0 | J9: 0.37724461 | K9: 39 | L9: 0 | M9: 0.49041799 | N9: 42 | O9: 8 | P9: 0.52270662 | Q9: 0.099563167 | R9: 12 | S9: 0.14546202 | T9: 3 | U9: 0.032288638 | V9: 5 | W9: 0.062226979 | X9: 44 | Y9: 9 | Z9: 0.54759742 | AA9: 0.11200856 | AB9: 49 | AC9: 11 | AD9: 0.60622557 | AE9: 0.13609145 | AF9: 50 | AG9: 10 | AH9: 0.61859752 | AI9: 0.1237195 | AJ9: =BattMobility!D87+cambio!D87+Claus2you!D87+CoopStroom!D87+Cozywheels!D87+Dégage!D87+Flexigo!D87+Klimaan!D87+Moovee!D87+Poppy!D87+'Mobilize Share'!D87+Stapp.in!D87 -> 50 | AK9: =BattMobility!E87+cambio!E87+Claus2you!E87+CoopStroom!E87+Cozywheels!E87+Dégage!E87+Flexigo!E87+Klimaan!E87+Moovee!E87+Poppy!E87+'Mobilize Share'!E87+Stapp.in!E87 -> 10 | AL9: =AJ9/G9*1000 -> 0.55402276 | AM9: =AK9/G9*1000 -> 0.11080455 | AN9: =AJ9-AB9 -> 1 | AO9: =AN9/AB9 -> 0.020408163 | AP9: =BattMobility!F87+cambio!F87+Claus2you!F87+CoopStroom!F87+Cozywheels!F87+Dégage!F87+Flexigo!F87+Klimaan!F87+Moovee!F87+Poppy!F87+'Mobilize Share'!F87+Stapp.in!F87 -> 52 | AQ9: =BattMobility!G87+cambio!G87+Claus2you!G87+CoopStroom!G87+Cozywheels!G87+Dégage!G87+Flexigo!G87+Klimaan!G87+Moovee!G87+Poppy!G87+'Mobilize Share'!G87+Stapp.in!G87 -> 11 | AR9: =AP9/G9*1000 -> 0.57618367 | AS9: =AQ9/G9*1000 -> 0.12188501 | AT9: =AP9-AF9 -> 2 | AU9: 161.656 | AV9: 111.656
A10: Merelbeke-Melle | B10: Oost-Vlaanderen | C10: 44088 | D10: 24886 | E10: 25200 | F10: 25229 | G10: 37369 | H10: 26 | I10: 1 | J10: 1.0447641 | K10: 30 | L10: 0 | M10: 1.2054971 | N10: 28 | O10: 6 | P10: 1.1111111 | Q10: 0.23809524 | R10: 2 | S10: 0.066346987 | T10: -2 | U10: -0.094385956 | V10: 19 | W10: 0.75396825 | X10: 27 | Y10: 3 | Z10: 1.0714286 | AA10: 0.11904762 | AB10: =32+'overzicht voor jun 25'!AA184 -> 42 | AC10: 7 | AD10: 1.2683816 | AE10: 0.27745848 | AF10: 36 | AG10: 10 | AH10: 1.4269293 | AI10: 0.39636926 | AJ10: =BattMobility!D176+cambio!D176+Claus2you!D176+CoopStroom!D176+Cozywheels!D176+Dégage!D176+Flexigo!D176+Klimaan!D176+Moovee!D176+Poppy!D176+'Mobilize Share'!D176+Stapp.in!D176 -> 52 | AK10: =BattMobility!E176+cambio!E176+Claus2you!E176+CoopStroom!E176+Cozywheels!E176+Dégage!E176+Flexigo!E176+Klimaan!E176+Moovee!E176+Poppy!E176+'Mobilize Share'!E176+Stapp.in!E176 -> 17 | AL10: =AJ10/G10*1000 -> 1.3915277 | AM10: =AK10/G10*1000 -> 0.45492253 | AN10: =AJ10-AB10 -> 10 | AO10: =AN10/AB10 -> 0.23809524 | AP10: =BattMobility!F176+cambio!F176+Claus2you!F176+CoopStroom!F176+Cozywheels!F176+Dégage!F176+Flexigo!F176+Klimaan!F176+Moovee!F176+Poppy!F176+'Mobilize Share'!F176+Stapp.in!F176 -> 50 | AQ10: =BattMobility!G176+cambio!G176+Claus2you!G176+CoopStroom!G176+Cozywheels!G176+Dégage!G176+Flexigo!G176+Klimaan!G176+Moovee!G176+Poppy!G176+'Mobilize Share'!G176+Stapp.in!G176 -> 15 | AR10: =AP10/G10*1000 -> 1.3380074 | AS10: =AQ10/G10*1000 -> 0.40140223 | AT10: =AP10-AF10 -> 14 | AU10: 50.458 | AV10: 14.458
A11: Turnhout | B11: Antwerpen | C11: 13040 | D11: 46372 | E11: 46923 | F11: 47305 | G11: 47965 | H11: 22 | I11: 0 | J11: 0.47442422 | K11: 22 | L11: 0 | M11: 0.47442422 | N11: 21 | O11: 6 | P11: 0.44754172 | Q11: 0.12786906 | R11: -1 | S11: -0.026882504 | T11: -1 | U11: -0.026882504 | V11: 10 | W11: 0.2131151 | X11: 29 | Y11: 8 | Z11: 0.6180338 | AA11: 0.17049208 | AB11: 32 | AC11: 12 | AD11: 0.67646126 | AE11: 0.25367297 | AF11: 40 | AG11: 17 | AH11: 0.84557658 | AI11: 0.35937005 | AJ11: =BattMobility!D247+cambio!D247+Claus2you!D247+CoopStroom!D247+Cozywheels!D247+Dégage!D247+Flexigo!D247+Klimaan!D247+Moovee!D247+Poppy!D247+'Mobilize Share'!D247+Stapp.in!D247 -> 43 | AK11: =BattMobility!E247+cambio!E247+Claus2you!E247+CoopStroom!E247+Cozywheels!E247+Dégage!E247+Flexigo!E247+Klimaan!E247+Moovee!E247+Poppy!E247+'Mobilize Share'!E247+Stapp.in!E247 -> 17 | AL11: =AJ11/G11*1000 -> 0.89648702 | AM11: =AK11/G11*1000 -> 0.3544251 | AN11: =AJ11-AB11 -> 11 | AO11: =AN11/AB11 -> 0.34375 | AP11: =BattMobility!F247+cambio!F247+Claus2you!F247+CoopStroom!F247+Cozywheels!F247+Dégage!F247+Flexigo!F247+Klimaan!F247+Moovee!F247+Poppy!F247+'Mobilize Share'!F247+Stapp.in!F247 -> 44 | AQ11: =BattMobility!G247+cambio!G247+Claus2you!G247+CoopStroom!G247+Cozywheels!G247+Dégage!G247+Flexigo!G247+Klimaan!G247+Moovee!G247+Poppy!G247+'Mobilize Share'!G247+Stapp.in!G247 -> 17 | AR11: =AP11/G11*1000 -> 0.91733556 | AS11: =AQ11/G11*1000 -> 0.3544251 | AT11: =AP11-AF11 -> 4 | AU11: 94.61 | AV11: 54.61
A12: Deinze | B12: Oost-Vlaanderen | C12: 44083 | D12: 44315 | E12: 44930 | F12: 45471 | G12: 46026 | H12: 20 | I12: 0 | J12: 0.45131445 | K12: 21 | L12: 0 | M12: 0.47388018 | N12: 25 | O12: 0 | P12: 0.5564211 | Q12: 0 | R12: 5 | S12: 0.10510665 | T12: 4 | U12: 0.082540923 | V12: 10 | W12: 0.22256844 | X12: 29 | Y12: 0 | Z12: 0.64544848 | AA12: 0 | AB12: 32 | AC12: 0 | AD12: 0.70374524 | AE12: 0 | AF12: 35 | AG12: 1 | AH12: 0.76972136 | AI12: 0.021992039 | AJ12: =BattMobility!D51+cambio!D51+Claus2you!D51+CoopStroom!D51+Cozywheels!D51+Dégage!D51+Flexigo!D51+Klimaan!D51+Moovee!D51+Poppy!D51+'Mobilize Share'!D51+Stapp.in!D51 -> 35 | AK12: =BattMobility!E51+cambio!E51+Claus2you!E51+CoopStroom!E51+Cozywheels!E51+Dégage!E51+Flexigo!E51+Klimaan!E51+Moovee!E51+Poppy!E51+'Mobilize Share'!E51+Stapp.in!E51 -> 1 | AL12: =AJ12/G12*1000 -> 0.76043975 | AM12: =AK12/G12*1000 -> 0.02172685 | AN12: =AJ12-AB12 -> 3 | AO12: =AN12/AB12 -> 0.09375 | AP12: =BattMobility!F51+cambio!F51+Claus2you!F51+CoopStroom!F51+Cozywheels!F51+Dégage!F51+Flexigo!F51+Klimaan!F51+Moovee!F51+Poppy!F51+'Mobilize Share'!F51+Stapp.in!F51 -> 38 | AQ12: =BattMobility!G51+cambio!G51+Claus2you!G51+CoopStroom!G51+Cozywheels!G51+Dégage!G51+Flexigo!G51+Klimaan!G51+Moovee!G51+Poppy!G51+'Mobilize Share'!G51+Stapp.in!G51 -> 1 | AR12: =AP12/G12*1000 -> 0.8256203 | AS12: =AQ12/G12*1000 -> 0.02172685 | AT12: =AP12-AF12 -> 3 | AU12: 90.942 | AV12: 55.942
A13: Roeselare | B13: West-Vlaanderen | C13: 36015 | D13: 64495 | E13: 65468 | F13: 66262 | G13: 66888 | H13: 18 | I13: 4 | J13: 0.2790914 | K13: 15 | L13: 4 | M13: 0.23257617 | N13: 14 | O13: 3 | P13: 0.21384493 | Q13: 0.045823914 | R13: -4 | S13: -0.065246471 | T13: -1 | U13: -0.018731237 | V13: 6 | W13: 0.091647828 | X13: 19 | Y13: 3 | Z13: 0.29021812 | AA13: 0.045823914 | AB13: 25 | AC13: 3 | AD13: 0.37729015 | AE13: 0.045274818 | AF13: 28 | AG13: 5 | AH13: 0.42256497 | AI13: 0.07545803 | AJ13: =BattMobility!D214+cambio!D214+Claus2you!D214+CoopStroom!D214+Cozywheels!D214+Dégage!D214+Flexigo!D214+Klimaan!D214+Moovee!D214+Poppy!D214+'Mobilize Share'!D214+Stapp.in!D214 -> 29 | AK13: =BattMobility!E214+cambio!E214+Claus2you!E214+CoopStroom!E214+Cozywheels!E214+Dégage!E214+Flexigo!E214+Klimaan!E214+Moovee!E214+Poppy!E214+'Mobilize Share'!E214+Stapp.in!E214 -> 7 | AL13: =AJ13/G13*1000 -> 0.43356058 | AM13: =AK13/G13*1000 -> 0.10465255 | AN13: =AJ13-AB13 -> 4 | AO13: =AN13/AB13 -> 0.16 | AP13: =BattMobility!F214+cambio!F214+Claus2you!F214+CoopStroom!F214+Cozywheels!F214+Dégage!F214+Flexigo!F214+Klimaan!F214+Moovee!F214+Poppy!F214+'Mobilize Share'!F214+Stapp.in!F214 -> 34 | AQ13: =BattMobility!G214+cambio!G214+Claus2you!G214+CoopStroom!G214+Cozywheels!G214+Dégage!G214+Flexigo!G214+Klimaan!G214+Moovee!G214+Poppy!G214+'Mobilize Share'!G214+Stapp.in!G214 -> 6 | AR13: =AP13/G13*1000 -> 0.5083124 | AS13: =AQ13/G13*1000 -> 0.089702189 | AT13: =AP13-AF13 -> 6 | AU13: 132.524 | AV13: 104.524
A14: Oostende | B14: West-Vlaanderen | C14: 35013 | D14: 71557 | E14: 72175 | F14: 72586 | G14: 72817 | H14: 21 | I14: 0 | J14: 0.29347234 | K14: 23 | L14: 0 | M14: 0.32142208 | N14: 27 | O14: 1 | P14: 0.37409075 | Q14: 0.013855213 | R14: 6 | S14: 0.080618415 | T14: 4 | U14: 0.052668669 | V14: 5 | W14: 0.069276065 | X14: 32 | Y14: 1 | Z14: 0.44336682 | AA14: 0.013855213 | AB14: 32 | AC14: 1 | AD14: 0.44085636 | AE14: 0.013776761 | AF14: 36 | AG14: 1 | AH14: 0.49596341 | AI14: 0.013776761 | AJ14: =BattMobility!D190+cambio!D190+Claus2you!D190+CoopStroom!D190+Cozywheels!D190+Dégage!D190+Flexigo!D190+Klimaan!D190+Moovee!D190+Poppy!D190+'Mobilize Share'!D190+Stapp.in!D190 -> 38 | AK14: =BattMobility!E190+cambio!E190+Claus2you!E190+CoopStroom!E190+Cozywheels!E190+Dégage!E190+Flexigo!E190+Klimaan!E190+Moovee!E190+Poppy!E190+'Mobilize Share'!E190+Stapp.in!E190 -> 1 | AL14: =AJ14/G14*1000 -> 0.52185616 | AM14: =AK14/G14*1000 -> 0.013733057 | AN14: =AJ14-AB14 -> 6 | AO14: =AN14/AB14 -> 0.1875 | AP14: =BattMobility!F190+cambio!F190+Claus2you!F190+CoopStroom!F190+Cozywheels!F190+Dégage!F190+Flexigo!F190+Klimaan!F190+Moovee!F190+Poppy!F190+'Mobilize Share'!F190+Stapp.in!F190 -> 34 | AQ14: =BattMobility!G190+cambio!G190+Claus2you!G190+CoopStroom!G190+Cozywheels!G190+Dégage!G190+Flexigo!G190+Klimaan!G190+Moovee!G190+Poppy!G190+'Mobilize Share'!G190+Stapp.in!G190 -> 2 | AR14: =AP14/G14*1000 -> 0.46692393 | AS14: =AQ14/G14*1000 -> 0.027466114 | AT14: =AP14-AF14 -> -2 | AU14: 145.172 | AV14: 109.172
A15: Aalst | B15: Oost-Vlaanderen | C15: 41002 | D15: 88854 | E15: 90068 | F15: 90995 | G15: 92131 | H15: 20 | I15: 0 | J15: 0.22508835 | K15: 19 | L15: 0 | M15: 0.21383393 | N15: 21 | O15: 6 | P15: 0.23315717 | Q15: 0.066616334 | R15: 1 | S15: 0.008068823 | T15: 2 | U15: 0.01932324 | V15: 1 | W15: 0.011102722 | X15: 26 | Y15: 5 | Z15: 0.28867078 | AA15: 0.055513612 | AB15: 34 | AC15: 10 | AD15: 0.3736469 | AE15: 0.10989615 | AF15: 38 | AG15: 10 | AH15: 0.41760536 | AI15: 0.10989615 | AJ15: =BattMobility!D2+cambio!D2+Claus2you!D2+CoopStroom!D2+Cozywheels!D2+Dégage!D2+Flexigo!D2+Klimaan!D2+Moovee!D2+Poppy!D2+'Mobilize Share'!D2+Stapp.in!D2 -> 34 | AK15: =BattMobility!E2+cambio!E2+Claus2you!E2+CoopStroom!E2+Cozywheels!E2+Dégage!E2+Flexigo!E2+Klimaan!E2+Moovee!E2+Poppy!E2+'Mobilize Share'!E2+Stapp.in!E2 -> 8 | AL15: =AJ15/G15*1000 -> 0.36903974 | AM15: =AK15/G15*1000 -> 0.086832879 | AN15: =AJ15-AB15 -> 0 | AO15: =AN15/AB15 -> 0 | AP15: =BattMobility!F2+cambio!F2+Claus2you!F2+CoopStroom!F2+Cozywheels!F2+Dégage!F2+Flexigo!F2+Klimaan!F2+Moovee!F2+Poppy!F2+'Mobilize Share'!F2+Stapp.in!F2 -> 34 | AQ15: =BattMobility!G2+cambio!G2+Claus2you!G2+CoopStroom!G2+Cozywheels!G2+Dégage!G2+Flexigo!G2+Klimaan!G2+Moovee!G2+Poppy!G2+'Mobilize Share'!G2+Stapp.in!G2 -> 10 | AR15: =AP15/G15*1000 -> 0.36903974 | AS15: =AQ15/G15*1000 -> 0.1085411 | AT15: =AP15-AF15 -> -4 | AU15: 181.99 | AV15: 143.99
A16: Mortsel | B16: Antwerpen | C16: 11029 | D16: 26189 | E16: 26391 | F16: 26588 | G16: 26736 | H16: 26 | I16: 4 | J16: 0.99278323 | K16: 35 | L16: 6 | M16: 1.336439 | N16: 61 | O16: 5 | P16: 2.311394 | Q16: 0.18945853 | R16: 35 | S16: 1.3186108 | T16: 26 | U16: 0.97495507 | V16: 4 | W16: 0.15156682 | X16: 63 | Y16: 1 | Z16: 2.3871774 | AA16: 0.037891706 | AB16: 66 | AC16: 4 | AD16: 2.4823229 | AE16: 0.15044381 | AF16: 36 | AG16: 4 | AH16: 1.3539943 | AI16: 0.15044381 | AJ16: =BattMobility!D182+cambio!D182+Claus2you!D182+CoopStroom!D182+Cozywheels!D182+Dégage!D182+Flexigo!D182+Klimaan!D182+Moovee!D182+Poppy!D182+'Mobilize Share'!D182+Stapp.in!D182 -> 33 | AK16: =BattMobility!E182+cambio!E182+Claus2you!E182+CoopStroom!E182+Cozywheels!E182+Dégage!E182+Flexigo!E182+Klimaan!E182+Moovee!E182+Poppy!E182+'Mobilize Share'!E182+Stapp.in!E182 -> 3 | AL16: =AJ16/G16*1000 -> 1.2342908 | AM16: =AK16/G16*1000 -> 0.11220826 | AN16: =AJ16-AB16 -> -33 | AO16: =AN16/AB16 -> -0.5 | AP16: =BattMobility!F182+cambio!F182+Claus2you!F182+CoopStroom!F182+Cozywheels!F182+Dégage!F182+Flexigo!F182+Klimaan!F182+Moovee!F182+Poppy!F182+'Mobilize Share'!F182+Stapp.in!F182 -> 33 | AQ16: =BattMobility!G182+cambio!G182+Claus2you!G182+CoopStroom!G182+Cozywheels!G182+Dégage!G182+Flexigo!G182+Klimaan!G182+Moovee!G182+Poppy!G182+'Mobilize Share'!G182+Stapp.in!G182 -> 3 | AR16: =AP16/G16*1000 -> 1.2342908 | AS16: =AQ16/G16*1000 -> 0.11220826 | AT16: =AP16-AF16 -> -3 | AU16: 53.176 | AV16: 17.176
A17: Beveren-Kruibeke-Zwijndrecht | B17: Oost-Vlaanderen | C17: 46030 | D17: 49531 | E17: 50300 | F17: 50838 | G17: 87927 | H17: 9 | I17: 0 | J17: 0.18170439 | K17: 7 | L17: 0 | M17: 0.14132563 | N17: 8 | O17: 2 | P17: 0.15904573 | Q17: 0.039761431 | R17: -1 | S17: -0.022658662 | T17: 1 | U17: 0.017720091 | V17: 0 | W17: 0 | X17: 8 | Y17: 2 | Z17: 0.15904573 | AA17: 0.039761431 | AB17: =10+'overzicht voor jun 25'!AA144+'overzicht voor jun 25'!AA301 -> 23 | AC17: =4+'overzicht voor jun 25'!AB301+'overzicht voor jun 25'!AB144 -> 9 | AD17: 0.19670325 | AE17: 0.078681301 | AF17: 11 | AG17: 5 | AH17: 0.21637358 | AI17: 0.098351627 | AJ17: =BattMobility!D29+cambio!D29+Claus2you!D29+CoopStroom!D29+Cozywheels!D29+Dégage!D29+Flexigo!D29+Klimaan!D29+Moovee!D29+Poppy!D29+'Mobilize Share'!D29+Stapp.in!D29 -> 30 | AK17: =BattMobility!E29+cambio!E29+Claus2you!E29+CoopStroom!E29+Cozywheels!E29+Dégage!E29+Flexigo!E29+Klimaan!E29+Moovee!E29+Poppy!E29+'Mobilize Share'!E29+Stapp.in!E29 -> 13 | AL17: =AJ17/G17*1000 -> 0.34119213 | AM17: =AK17/G17*1000 -> 0.14784992 | AN17: =AJ17-AB17 -> 7 | AO17: =AN17/AB17 -> 0.30434783 | AP17: =BattMobility!F29+cambio!F29+Claus2you!F29+CoopStroom!F29+Cozywheels!F29+Dégage!F29+Flexigo!F29+Klimaan!F29+Moovee!F29+Poppy!F29+'Mobilize Share'!F29+Stapp.in!F29 -> 30 | AQ17: =BattMobility!G29+cambio!G29+Claus2you!G29+CoopStroom!G29+Cozywheels!G29+Dégage!G29+Flexigo!G29+Klimaan!G29+Moovee!G29+Poppy!G29+'Mobilize Share'!G29+Stapp.in!G29 -> 13 | AR17: =AP17/G17*1000 -> 0.34119213 | AS17: =AQ17/G17*1000 -> 0.14784992 | AT17: =AP17-AF17 -> 19 | AU17: 101.676 | AV17: 90.676
A18: Lier | B18: Antwerpen | C18: 12021 | D18: 37309 | E18: 37909 | F18: 38210 | G18: 38517 | H18: 19 | I18: 0 | J18: 0.5092605 | K18: 21 | L18: 0 | M18: 0.56286687 | N18: 28 | O18: 2 | P18: 0.73861088 | Q18: 0.05275792 | R18: 9 | S18: 0.22935038 | T18: 7 | U18: 0.17574402 | V18: 8 | W18: 0.21103168 | X18: 29 | Y18: 1 | Z18: 0.76498984 | AA18: 0.02637896 | AB18: 32 | AC18: 1 | AD18: 0.8374771 | AE18: 0.026171159 | AF18: 32 | AG18: 1 | AH18: 0.8374771 | AI18: 0.026171159 | AJ18: =BattMobility!D151+cambio!D151+Claus2you!D151+CoopStroom!D151+Cozywheels!D151+Dégage!D151+Flexigo!D151+Klimaan!D151+Moovee!D151+Poppy!D151+'Mobilize Share'!D151+Stapp.in!D151 -> 30 | AK18: =BattMobility!E151+cambio!E151+Claus2you!E151+CoopStroom!E151+Cozywheels!E151+Dégage!E151+Flexigo!E151+Klimaan!E151+Moovee!E151+Poppy!E151+'Mobilize Share'!E151+Stapp.in!E151 -> 1 | AL18: =AJ18/G18*1000 -> 0.77887686 | AM18: =AK18/G18*1000 -> 0.025962562 | AN18: =AJ18-AB18 -> -2 | AO18: =AN18/AB18 -> -0.0625 | AP18: =BattMobility!F151+cambio!F151+Claus2you!F151+CoopStroom!F151+Cozywheels!F151+Dégage!F151+Flexigo!F151+Klimaan!F151+Moovee!F151+Poppy!F151+'Mobilize Share'!F151+Stapp.in!F151 -> 29 | AQ18: =BattMobility!G151+cambio!G151+Claus2you!G151+CoopStroom!G151+Cozywheels!G151+Dégage!G151+Flexigo!G151+Klimaan!G151+Moovee!G151+Poppy!G151+'Mobilize Share'!G151+Stapp.in!G151 -> 1 | AR18: =AP18/G18*1000 -> 0.7529143 | AS18: =AQ18/G18*1000 -> 0.025962562 | AT18: =AP18-AF18 -> -3 | AU18: 76.42 | AV18: 44.42
A19: Herent | B19: Vlaams-Brabant | C19: 24038 | D19: 22430 | E19: 22723 | F19: 23007 | G19: 23081 | H19: 16 | I19: 0 | J19: 0.71333036 | K19: 14 | L19: 0 | M19: 0.62416407 | N19: 16 | O19: 4 | P19: 0.70413238 | Q19: 0.17603309 | R19: 0 | S19: -0.0091979842 | T19: 2 | U19: 0.079968311 | V19: 10 | W19: 0.44008274 | X19: 17 | Y19: 4 | Z19: 0.74814065 | AA19: 0.17603309 | AB19: 19 | AC19: 6 | AD19: 0.82583562 | AE19: 0.26079019 | AF19: 25 | AG19: 8 | AH19: 1.0866258 | AI19: 0.34772026 | AJ19: =BattMobility!D92+cambio!D92+Claus2you!D92+CoopStroom!D92+Cozywheels!D92+Dégage!D92+Flexigo!D92+Klimaan!D92+Moovee!D92+Poppy!D92+'Mobilize Share'!D92+Stapp.in!D92 -> 25 | AK19: =BattMobility!E92+cambio!E92+Claus2you!E92+CoopStroom!E92+Cozywheels!E92+Dégage!E92+Flexigo!E92+Klimaan!E92+Moovee!E92+Poppy!E92+'Mobilize Share'!E92+Stapp.in!E92 -> 8 | AL19: =AJ19/G19*1000 -> 1.083142 | AM19: =AK19/G19*1000 -> 0.34660543 | AN19: =AJ19-AB19 -> 6 | AO19: =AN19/AB19 -> 0.31578947 | AP19: =BattMobility!F92+cambio!F92+Claus2you!F92+CoopStroom!F92+Cozywheels!F92+Dégage!F92+Flexigo!F92+Klimaan!F92+Moovee!F92+Poppy!F92+'Mobilize Share'!F92+Stapp.in!F92 -> 23 | AQ19: =BattMobility!G92+cambio!G92+Claus2you!G92+CoopStroom!G92+Cozywheels!G92+Dégage!G92+Flexigo!G92+Klimaan!G92+Moovee!G92+Poppy!G92+'Mobilize Share'!G92+Stapp.in!G92 -> 7 | AR19: =AP19/G19*1000 -> 0.99649062 | AS19: =AQ19/G19*1000 -> 0.30327975 | AT19: =AP19-AF19 -> -2 | AU19: 46.014 | AV19: 21.014
A20: Halle | B20: Vlaams-Brabant | C20: 23027 | D20: 41284 | E20: 42047 | F20: 42595 | G20: 42884 | H20: 18 | I20: 1 | J20: 0.43600426 | K20: 13 | L20: 1 | M20: 0.31489197 | N20: 15 | O20: 5 | P20: 0.35674364 | Q20: 0.11891455 | R20: -3 | S20: -0.079260619 | T20: 2 | U20: 0.041851676 | V20: 9 | W20: 0.21404619 | X20: 17 | Y20: 4 | Z20: 0.40430946 | AA20: 0.095131638 | AB20: 18 | AC20: 4 | AD20: 0.42258481 | AE20: 0.093907736 | AF20: 21 | AG20: 3 | AH20: 0.49301561 | AI20: 0.070430802 | AJ20: =BattMobility!D83+cambio!D83+Claus2you!D83+CoopStroom!D83+Cozywheels!D83+Dégage!D83+Flexigo!D83+Klimaan!D83+Moovee!D83+Poppy!D83+'Mobilize Share'!D83+Stapp.in!D83 -> 21 | AK20: =BattMobility!E83+cambio!E83+Claus2you!E83+CoopStroom!E83+Cozywheels!E83+Dégage!E83+Flexigo!E83+Klimaan!E83+Moovee!E83+Poppy!E83+'Mobilize Share'!E83+Stapp.in!E83 -> 3 | AL20: =AJ20/G20*1000 -> 0.48969313 | AM20: =AK20/G20*1000 -> 0.069956161 | AN20: =AJ20-AB20 -> 3 | AO20: =AN20/AB20 -> 0.16666667 | AP20: =BattMobility!F83+cambio!F83+Claus2you!F83+CoopStroom!F83+Cozywheels!F83+Dégage!F83+Flexigo!F83+Klimaan!F83+Moovee!F83+Poppy!F83+'Mobilize Share'!F83+Stapp.in!F83 -> 22 | AQ20: =BattMobility!G83+cambio!G83+Claus2you!G83+CoopStroom!G83+Cozywheels!G83+Dégage!G83+Flexigo!G83+Klimaan!G83+Moovee!G83+Poppy!G83+'Mobilize Share'!G83+Stapp.in!G83 -> 3 | AR20: =AP20/G20*1000 -> 0.51301185 | AS20: =AQ20/G20*1000 -> 0.069956161 | AT20: =AP20-AF20 -> 1 | AU20: 85.19 | AV20: 64.19
A21: Destelbergen | B21: Oost-Vlaanderen | C21: 44013 | D21: 18856 | E21: 19097 | F21: 19110 | G21: 19088 | H21: 11 | I21: 0 | J21: 0.58336869 | K21: 13 | L21: 1 | M21: 0.68943572 | N21: 16 | O21: 4 | P21: 0.83782793 | Q21: 0.20945698 | R21: 5 | S21: 0.25445924 | T21: 3 | U21: 0.14839221 | V21: 12 | W21: 0.62837095 | X21: 16 | Y21: 4 | Z21: 0.83782793 | AA21: 0.20945698 | AB21: 17 | AC21: 3 | AD21: 0.8895866 | AE21: 0.15698587 | AF21: 18 | AG21: 4 | AH21: 0.94191523 | AI21: 0.2093145 | AJ21: =BattMobility!D56+cambio!D56+Claus2you!D56+CoopStroom!D56+Cozywheels!D56+Dégage!D56+Flexigo!D56+Klimaan!D56+Moovee!D56+Poppy!D56+'Mobilize Share'!D56+Stapp.in!D56 -> 19 | AK21: =BattMobility!E56+cambio!E56+Claus2you!E56+CoopStroom!E56+Cozywheels!E56+Dégage!E56+Flexigo!E56+Klimaan!E56+Moovee!E56+Poppy!E56+'Mobilize Share'!E56+Stapp.in!E56 -> 5 | AL21: =AJ21/G21*1000 -> 0.99538977 | AM21: =AK21/G21*1000 -> 0.26194468 | AN21: =AJ21-AB21 -> 2 | AO21: =AN21/AB21 -> 0.11764706 | AP21: =BattMobility!F56+cambio!F56+Claus2you!F56+CoopStroom!F56+Cozywheels!F56+Dégage!F56+Flexigo!F56+Klimaan!F56+Moovee!F56+Poppy!F56+'Mobilize Share'!F56+Stapp.in!F56 -> 21 | AQ21: =BattMobility!G56+cambio!G56+Claus2you!G56+CoopStroom!G56+Cozywheels!G56+Dégage!G56+Flexigo!G56+Klimaan!G56+Moovee!G56+Poppy!G56+'Mobilize Share'!G56+Stapp.in!G56 -> 6 | AR21: =AP21/G21*1000 -> 1.1001676 | AS21: =AQ21/G21*1000 -> 0.31433361 | AT21: =AP21-AF21 -> 3 | AU21: 38.22 | AV21: 20.22
A22: Lokeren | B22: Oost-Vlaanderen | C22: 46029 | D22: 42703 | E22: 43064 | F22: 43554 | G22: 50606 | H22: 9 | I22: 0 | J22: 0.21075803 | K22: 10 | L22: 0 | M22: 0.23417558 | N22: 10 | O22: 5 | P22: 0.23221252 | Q22: 0.11610626 | R22: 1 | S22: 0.021454495 | T22: 0 | U22: -0.001963064 | V22: 2 | W22: 0.046442504 | X22: 16 | Y22: 5 | Z22: 0.37154003 | AA22: 0.11610626 | AB22: =17+'overzicht voor jun 25'!AA192 -> 19 | AC22: 5 | AD22: 0.39032006 | AE22: 0.11480002 | AF22: 14 | AG22: 3 | AH22: 0.32144005 | AI22: 0.068880011 | AJ22: =BattMobility!D160+cambio!D160+Claus2you!D160+CoopStroom!D160+Cozywheels!D160+Dégage!D160+Flexigo!D160+Klimaan!D160+Moovee!D160+Poppy!D160+'Mobilize Share'!D160+Stapp.in!D160 -> 18 | AK22: =BattMobility!E160+cambio!E160+Claus2you!E160+CoopStroom!E160+Cozywheels!E160+Dégage!E160+Flexigo!E160+Klimaan!E160+Moovee!E160+Poppy!E160+'Mobilize Share'!E160+Stapp.in!E160 -> 4 | AL22: =AJ22/G22*1000 -> 0.35568905 | AM22: =AK22/G22*1000 -> 0.079042011 | AN22: =AJ22-AB22 -> -1 | AO22: =AN22/AB22 -> -0.052631579 | AP22: =BattMobility!F160+cambio!F160+Claus2you!F160+CoopStroom!F160+Cozywheels!F160+Dégage!F160+Flexigo!F160+Klimaan!F160+Moovee!F160+Poppy!F160+'Mobilize Share'!F160+Stapp.in!F160 -> 21 | AQ22: =BattMobility!G160+cambio!G160+Claus2you!G160+CoopStroom!G160+Cozywheels!G160+Dégage!G160+Flexigo!G160+Klimaan!G160+Moovee!G160+Poppy!G160+'Mobilize Share'!G160+Stapp.in!G160 -> 6 | AR22: =AP22/G22*1000 -> 0.41497056 | AS22: =AQ22/G22*1000 -> 0.11856302 | AT22: =AP22-AF22 -> 7 | AU22: 87.108 | AV22: 73.108
A23: Harelbeke | B23: West-Vlaanderen | C23: 34013 | D23: 29095 | E23: 29574 | F23: 29904 | G23: 30311 | H23: 14 | I23: 2 | J23: 0.48118233 | K23: 16 | L23: 2 | M23: 0.54992267 | N23: 16 | O23: 12 | P23: 0.54101576 | Q23: 0.40576182 | R23: 2 | S23: 0.059833423 | T23: 0 | U23: -0.00890691 | V23: 2 | W23: 0.06762697 | X23: 17 | Y23: 12 | Z23: 0.57482924 | AA23: 0.40576182 | AB23: 17 | AC23: 12 | AD23: 0.56848582 | AE23: 0.40128411 | AF23: 20 | AG23: 14 | AH23: 0.66880685 | AI23: 0.46816479 | AJ23: =BattMobility!D86+cambio!D86+Claus2you!D86+CoopStroom!D86+Cozywheels!D86+Dégage!D86+Flexigo!D86+Klimaan!D86+Moovee!D86+Poppy!D86+'Mobilize Share'!D86+Stapp.in!D86 -> 18 | AK23: =BattMobility!E86+cambio!E86+Claus2you!E86+CoopStroom!E86+Cozywheels!E86+Dégage!E86+Flexigo!E86+Klimaan!E86+Moovee!E86+Poppy!E86+'Mobilize Share'!E86+Stapp.in!E86 -> 12 | AL23: =AJ23/G23*1000 -> 0.59384382 | AM23: =AK23/G23*1000 -> 0.39589588 | AN23: =AJ23-AB23 -> 1 | AO23: =AN23/AB23 -> 0.058823529 | AP23: =BattMobility!F86+cambio!F86+Claus2you!F86+CoopStroom!F86+Cozywheels!F86+Dégage!F86+Flexigo!F86+Klimaan!F86+Moovee!F86+Poppy!F86+'Mobilize Share'!F86+Stapp.in!F86 -> 18 | AQ23: =BattMobility!G86+cambio!G86+Claus2you!G86+CoopStroom!G86+Cozywheels!G86+Dégage!G86+Flexigo!G86+Klimaan!G86+Moovee!G86+Poppy!G86+'Mobilize Share'!G86+Stapp.in!G86 -> 12 | AR23: =AP23/G23*1000 -> 0.59384382 | AS23: =AQ23/G23*1000 -> 0.39589588 | AT23: =AP23-AF23 -> -2 | AU23: 59.808 | AV23: 39.808
A24: Vilvoorde | B24: Vlaams-Brabant | C24: 23088 | D24: 46354 | E24: 46993 | F24: 47445 | G24: 48040 | H24: 7 | I24: 0 | J24: 0.15101178 | K24: 7 | L24: 0 | M24: 0.15101178 | N24: 8 | O24: 0 | P24: 0.17023812 | Q24: 0 | R24: 1 | S24: 0.019226342 | T24: 1 | U24: 0.019226342 | V24: 0 | W24: 0 | X24: 10 | Y24: 0 | Z24: 0.21279765 | AA24: 0 | AB24: 10 | AC24: 0 | AD24: 0.21077037 | AE24: 0 | AF24: 12 | AG24: 0 | AH24: 0.25292444 | AI24: 0 | AJ24: =BattMobility!D249+cambio!D249+Claus2you!D249+CoopStroom!D249+Cozywheels!D249+Dégage!D249+Flexigo!D249+Klimaan!D249+Moovee!D249+Poppy!D249+'Mobilize Share'!D249+Stapp.in!D249 -> 15 | AK24: =BattMobility!E249+cambio!E249+Claus2you!E249+CoopStroom!E249+Cozywheels!E249+Dégage!E249+Flexigo!E249+Klimaan!E249+Moovee!E249+Poppy!E249+'Mobilize Share'!E249+Stapp.in!E249 -> 0 | AL24: =AJ24/G24*1000 -> 0.3122398 | AM24: =AK24/G24*1000 -> 0 | AN24: =AJ24-AB24 -> 5 | AO24: =AN24/AB24 -> 0.5 | AP24: =BattMobility!F249+cambio!F249+Claus2you!F249+CoopStroom!F249+Cozywheels!F249+Dégage!F249+Flexigo!F249+Klimaan!F249+Moovee!F249+Poppy!F249+'Mobilize Share'!F249+Stapp.in!F249 -> 17 | AQ24: =BattMobility!G249+cambio!G249+Claus2you!G249+CoopStroom!G249+Cozywheels!G249+Dégage!G249+Flexigo!G249+Klimaan!G249+Moovee!G249+Poppy!G249+'Mobilize Share'!G249+Stapp.in!G249 -> 0 | AR24: =AP24/G24*1000 -> 0.35387177 | AS24: =AQ24/G24*1000 -> 0 | AT24: =AP24-AF24 -> 5 | AU24: 94.89 | AV24: 82.89
A25: Nazareth-De Pinte | B25: Oost-Vlaanderen | C25: 44086 | D25: 12040 | E25: 12214 | F25: 12305 | G25: 23574 | H25: 1 | I25: 0 | J25: 0.083056478 | K25: 6 | L25: 0 | M25: 0.49833887 | N25: 5 | O25: 0 | P25: 0.4093663 | Q25: 0 | R25: 4 | S25: 0.32630982 | T25: -1 | U25: -0.088972569 | V25: 5 | W25: 0.4093663 | X25: 5 | Y25: 2 | Z25: 0.4093663 | AA25: 0.16374652 | AB25: =4+'overzicht voor jun 25'!AA52 -> 13 | AC25: =2+'overzicht voor jun 25'!AB52 -> 3 | AD25: 0.32507111 | AE25: 0.16253555 | AF25: 8 | AG25: 2 | AH25: 0.65014222 | AI25: 0.16253555 | AJ25: =BattMobility!D183+cambio!D183+Claus2you!D183+CoopStroom!D183+Cozywheels!D183+Dégage!D183+Flexigo!D183+Klimaan!D183+Moovee!D183+Poppy!D183+'Mobilize Share'!D183+Stapp.in!D183 -> 15 | AK25: =BattMobility!E183+cambio!E183+Claus2you!E183+CoopStroom!E183+Cozywheels!E183+Dégage!E183+Flexigo!E183+Klimaan!E183+Moovee!E183+Poppy!E183+'Mobilize Share'!E183+Stapp.in!E183 -> 4 | AL25: =AJ25/G25*1000 -> 0.63629422 | AM25: =AK25/G25*1000 -> 0.16967846 | AN25: =AJ25-AB25 -> 2 | AO25: =AN25/AB25 -> 0.15384615 | AP25: =BattMobility!F183+cambio!F183+Claus2you!F183+CoopStroom!F183+Cozywheels!F183+Dégage!F183+Flexigo!F183+Klimaan!F183+Moovee!F183+Poppy!F183+'Mobilize Share'!F183+Stapp.in!F183 -> 16 | AQ25: =BattMobility!G183+cambio!G183+Claus2you!G183+CoopStroom!G183+Cozywheels!G183+Dégage!G183+Flexigo!G183+Klimaan!G183+Moovee!G183+Poppy!G183+'Mobilize Share'!G183+Stapp.in!G183 -> 6 | AR25: =AP25/G25*1000 -> 0.67871384 | AS25: =AQ25/G25*1000 -> 0.25451769 | AT25: =AP25-AF25 -> 8 | AU25: 24.61 | AV25: 16.61
A26: Ieper | B26: West-Vlaanderen | C26: 33011 | D26: 35039 | E26: 35387 | F26: 35550 | G26: 35587 | H26: 9 | I26: 0 | J26: 0.25685665 | K26: 6 | L26: 0 | M26: 0.17123776 | N26: 9 | O26: 0 | P26: 0.25433069 | Q26: 0 | R26: 0 | S26: -0.002525959 | T26: 3 | U26: 0.083092923 | V26: 2 | W26: 0.05651793 | X26: 12 | Y26: 0 | Z26: 0.33910758 | AA26: 0 | AB26: 14 | AC26: 1 | AD26: 0.39381153 | AE26: 0.028129395 | AF26: 15 | AG26: 1 | AH26: 0.42194093 | AI26: 0.028129395 | AJ26: =BattMobility!D113+cambio!D113+Claus2you!D113+CoopStroom!D113+Cozywheels!D113+Dégage!D113+Flexigo!D113+Klimaan!D113+Moovee!D113+Poppy!D113+'Mobilize Share'!D113+Stapp.in!D113 -> 15 | AK26: =BattMobility!E113+cambio!E113+Claus2you!E113+CoopStroom!E113+Cozywheels!E113+Dégage!E113+Flexigo!E113+Klimaan!E113+Moovee!E113+Poppy!E113+'Mobilize Share'!E113+Stapp.in!E113 -> 1 | AL26: =AJ26/G26*1000 -> 0.42150223 | AM26: =AK26/G26*1000 -> 0.028100149 | AN26: =AJ26-AB26 -> 1 | AO26: =AN26/AB26 -> 0.071428571 | AP26: =BattMobility!F113+cambio!F113+Claus2you!F113+CoopStroom!F113+Cozywheels!F113+Dégage!F113+Flexigo!F113+Klimaan!F113+Moovee!F113+Poppy!F113+'Mobilize Share'!F113+Stapp.in!F113 -> 16 | AQ26: =BattMobility!G113+cambio!G113+Claus2you!G113+CoopStroom!G113+Cozywheels!G113+Dégage!G113+Flexigo!G113+Klimaan!G113+Moovee!G113+Poppy!G113+'Mobilize Share'!G113+Stapp.in!G113 -> 1 | AR26: =AP26/G26*1000 -> 0.44960238 | AS26: =AQ26/G26*1000 -> 0.028100149 | AT26: =AP26-AF26 -> 1 | AU26: 71.1 | AV26: 56.1
A27: Oudenaarde | B27: Oost-Vlaanderen | C27: 45035 | D27: 31866 | E27: 32482 | F27: 32702 | G27: 32930 | H27: 7 | I27: 0 | J27: 0.21966987 | K27: 8 | L27: 0 | M27: 0.25105128 | N27: 8 | O27: 3 | P27: 0.24629025 | Q27: 0.092358845 | R27: 1 | S27: 0.026620385 | T27: 0 | U27: -0.0047610242 | V27: 4 | W27: 0.12314513 | X27: 7 | Y27: 3 | Z27: 0.21550397 | AA27: 0.092358845 | AB27: 8 | AC27: 5 | AD27: 0.24463336 | AE27: 0.15289585 | AF27: 10 | AG27: 7 | AH27: 0.30579169 | AI27: 0.21405419 | AJ27: =BattMobility!D197+cambio!D197+Claus2you!D197+CoopStroom!D197+Cozywheels!D197+Dégage!D197+Flexigo!D197+Klimaan!D197+Moovee!D197+Poppy!D197+'Mobilize Share'!D197+Stapp.in!D197 -> 10 | AK27: =BattMobility!E197+cambio!E197+Claus2you!E197+CoopStroom!E197+Cozywheels!E197+Dégage!E197+Flexigo!E197+Klimaan!E197+Moovee!E197+Poppy!E197+'Mobilize Share'!E197+Stapp.in!E197 -> 8 | AL27: =AJ27/G27*1000 -> 0.30367446 | AM27: =AK27/G27*1000 -> 0.24293957 | AN27: =AJ27-AB27 -> 2 | AO27: =AN27/AB27 -> 0.25 | AP27: =BattMobility!F197+cambio!F197+Claus2you!F197+CoopStroom!F197+Cozywheels!F197+Dégage!F197+Flexigo!F197+Klimaan!F197+Moovee!F197+Poppy!F197+'Mobilize Share'!F197+Stapp.in!F197 -> 15 | AQ27: =BattMobility!G197+cambio!G197+Claus2you!G197+CoopStroom!G197+Cozywheels!G197+Dégage!G197+Flexigo!G197+Klimaan!G197+Moovee!G197+Poppy!G197+'Mobilize Share'!G197+Stapp.in!G197 -> 9 | AR27: =AP27/G27*1000 -> 0.45551169 | AS27: =AQ27/G27*1000 -> 0.27330701 | AT27: =AP27-AF27 -> 5 | AU27: 65.404 | AV27: 55.404
A28: Rotselaar | B28: Vlaams-Brabant | C28: 24094 | D28: 17294 | E28: 17499 | F28: 17672 | G28: 17689 | H28: 5 | I28: 0 | J28: 0.28911761 | K28: 5 | L28: 0 | M28: 0.28911761 | N28: 7 | O28: 0 | P28: 0.40002286 | Q28: 0 | R28: 2 | S28: 0.11090525 | T28: 2 | U28: 0.11090525 | V28: 0 | W28: 0 | X28: 7 | Y28: 0 | Z28: 0.40002286 | AA28: 0 | AB28: 10 | AC28: 0 | AD28: 0.56586691 | AE28: 0 | AF28: 12 | AG28: 1 | AH28: 0.67904029 | AI28: 0.056586691 | AJ28: =BattMobility!D217+cambio!D217+Claus2you!D217+CoopStroom!D217+Cozywheels!D217+Dégage!D217+Flexigo!D217+Klimaan!D217+Moovee!D217+Poppy!D217+'Mobilize Share'!D217+Stapp.in!D217 -> 12 | AK28: =BattMobility!E217+cambio!E217+Claus2you!E217+CoopStroom!E217+Cozywheels!E217+Dégage!E217+Flexigo!E217+Klimaan!E217+Moovee!E217+Poppy!E217+'Mobilize Share'!E217+Stapp.in!E217 -> 1 | AL28: =AJ28/G28*1000 -> 0.6783877 | AM28: =AK28/G28*1000 -> 0.056532308 | AN28: =AJ28-AB28 -> 2 | AO28: =AN28/AB28 -> 0.2 | AP28: =BattMobility!F217+cambio!F217+Claus2you!F217+CoopStroom!F217+Cozywheels!F217+Dégage!F217+Flexigo!F217+Klimaan!F217+Moovee!F217+Poppy!F217+'Mobilize Share'!F217+Stapp.in!F217 -> 14 | AQ28: =BattMobility!G217+cambio!G217+Claus2you!G217+CoopStroom!G217+Cozywheels!G217+Dégage!G217+Flexigo!G217+Klimaan!G217+Moovee!G217+Poppy!G217+'Mobilize Share'!G217+Stapp.in!G217 -> 4 | AR28: =AP28/G28*1000 -> 0.79145231 | AS28: =AQ28/G28*1000 -> 0.22612923 | AT28: =AP28-AF28 -> 2 | AU28: 35.344 | AV28: 23.344
A29: Oostkamp | B29: West-Vlaanderen | C29: 31022 | D29: 23998 | E29: 24200 | F29: 24275 | G29: 24142 | H29: 4 | I29: 3 | J29: 0.16668056 | K29: 5 | L29: 3 | M29: 0.2083507 | N29: 7 | O29: 4 | P29: 0.2892562 | Q29: 0.16528926 | R29: 3 | S29: 0.12257564 | T29: 2 | U29: 0.080905502 | V29: 4 | W29: 0.16528926 | X29: 8 | Y29: 3 | Z29: 0.33057851 | AA29: 0.12396694 | AB29: 8 | AC29: 3 | AD29: 0.32955716 | AE29: 0.12358393 | AF29: 11 | AG29: 4 | AH29: 0.45314109 | AI29: 0.16477858 | AJ29: =BattMobility!D192+cambio!D192+Claus2you!D192+CoopStroom!D192+Cozywheels!D192+Dégage!D192+Flexigo!D192+Klimaan!D192+Moovee!D192+Poppy!D192+'Mobilize Share'!D192+Stapp.in!D192 -> 11 | AK29: =BattMobility!E192+cambio!E192+Claus2you!E192+CoopStroom!E192+Cozywheels!E192+Dégage!E192+Flexigo!E192+Klimaan!E192+Moovee!E192+Poppy!E192+'Mobilize Share'!E192+Stapp.in!E192 -> 4 | AL29: =AJ29/G29*1000 -> 0.45563748 | AM29: =AK29/G29*1000 -> 0.16568636 | AN29: =AJ29-AB29 -> 3 | AO29: =AN29/AB29 -> 0.375 | AP29: =BattMobility!F192+cambio!F192+Claus2you!F192+CoopStroom!F192+Cozywheels!F192+Dégage!F192+Flexigo!F192+Klimaan!F192+Moovee!F192+Poppy!F192+'Mobilize Share'!F192+Stapp.in!F192 -> 14 | AQ29: =BattMobility!G192+cambio!G192+Claus2you!G192+CoopStroom!G192+Cozywheels!G192+Dégage!G192+Flexigo!G192+Klimaan!G192+Moovee!G192+Poppy!G192+'Mobilize Share'!G192+Stapp.in!G192 -> 7 | AR29: =AP29/G29*1000 -> 0.57990225 | AS29: =AQ29/G29*1000 -> 0.28995112 | AT29: =AP29-AF29 -> 3 | AU29: 48.55 | AV29: 37.55
A30: Dendermonde | B30: Oost-Vlaanderen | C30: 42006 | D30: 46325 | E30: 46916 | F30: 47185 | G30: 47539 | H30: 5 | I30: 0 | J30: 0.10793308 | K30: 6 | L30: 0 | M30: 0.1295197 | N30: 7 | O30: 3 | P30: 0.14920283 | Q30: 0.06394407 | R30: 2 | S30: 0.041269749 | T30: 1 | U30: 0.019683133 | V30: 1 | W30: 0.02131469 | X30: 6 | Y30: 3 | Z30: 0.12788814 | AA30: 0.06394407 | AB30: 8 | AC30: 5 | AD30: 0.16954541 | AE30: 0.10596588 | AF30: 10 | AG30: 5 | AH30: 0.21193176 | AI30: 0.10596588 | AJ30: =BattMobility!D53+cambio!D53+Claus2you!D53+CoopStroom!D53+Cozywheels!D53+Dégage!D53+Flexigo!D53+Klimaan!D53+Moovee!D53+Poppy!D53+'Mobilize Share'!D53+Stapp.in!D53 -> 13 | AK30: =BattMobility!E53+cambio!E53+Claus2you!E53+CoopStroom!E53+Cozywheels!E53+Dégage!E53+Flexigo!E53+Klimaan!E53+Moovee!E53+Poppy!E53+'Mobilize Share'!E53+Stapp.in!E53 -> 5 | AL30: =AJ30/G30*1000 -> 0.27345969 | AM30: =AK30/G30*1000 -> 0.1051768 | AN30: =AJ30-AB30 -> 5 | AO30: =AN30/AB30 -> 0.625 | AP30: =BattMobility!F53+cambio!F53+Claus2you!F53+CoopStroom!F53+Cozywheels!F53+Dégage!F53+Flexigo!F53+Klimaan!F53+Moovee!F53+Poppy!F53+'Mobilize Share'!F53+Stapp.in!F53 -> 13 | AQ30: =BattMobility!G53+cambio!G53+Claus2you!G53+CoopStroom!G53+Cozywheels!G53+Dégage!G53+Flexigo!G53+Klimaan!G53+Moovee!G53+Poppy!G53+'Mobilize Share'!G53+Stapp.in!G53 -> 5 | AR30: =AP30/G30*1000 -> 0.27345969 | AS30: =AQ30/G30*1000 -> 0.1051768 | AT30: =AP30-AF30 -> 3 | AU30: 94.37 | AV30: 84.37
A31: Landen | B31: Vlaams-Brabant | C31: 24059 | D31: 16149 | E31: 16284 | F31: 16390 | G31: 16375 | H31: 2 | I31: 0 | J31: 0.12384668 | K31: 5 | L31: 0 | M31: 0.30961669 | N31: 5 | O31: 0 | P31: 0.30704986 | Q31: 0 | R31: 3 | S31: 0.18320319 | T31: 0 | U31: -0.0025668296 | V31: 3 | W31: 0.18422992 | X31: 10 | Y31: 4 | Z31: 0.61409973 | AA31: 0.24563989 | AB31: 9 | AC31: 4 | AD31: 0.54911531 | AE31: 0.24405125 | AF31: 12 | AG31: 8 | AH31: 0.73215375 | AI31: 0.4881025 | AJ31: =BattMobility!D140+cambio!D140+Claus2you!D140+CoopStroom!D140+Cozywheels!D140+Dégage!D140+Flexigo!D140+Klimaan!D140+Moovee!D140+Poppy!D140+'Mobilize Share'!D140+Stapp.in!D140 -> 12 | AK31: =BattMobility!E140+cambio!E140+Claus2you!E140+CoopStroom!E140+Cozywheels!E140+Dégage!E140+Flexigo!E140+Klimaan!E140+Moovee!E140+Poppy!E140+'Mobilize Share'!E140+Stapp.in!E140 -> 8 | AL31: =AJ31/G31*1000 -> 0.73282443 | AM31: =AK31/G31*1000 -> 0.48854962 | AN31: =AJ31-AB31 -> 3 | AO31: =AN31/AB31 -> 0.33333333 | AP31: =BattMobility!F140+cambio!F140+Claus2you!F140+CoopStroom!F140+Cozywheels!F140+Dégage!F140+Flexigo!F140+Klimaan!F140+Moovee!F140+Poppy!F140+'Mobilize Share'!F140+Stapp.in!F140 -> 12 | AQ31: =BattMobility!G140+cambio!G140+Claus2you!G140+CoopStroom!G140+Cozywheels!G140+Dégage!G140+Flexigo!G140+Klimaan!G140+Moovee!G140+Poppy!G140+'Mobilize Share'!G140+Stapp.in!G140 -> 8 | AR31: =AP31/G31*1000 -> 0.73282443 | AS31: =AQ31/G31*1000 -> 0.48854962 | AT31: =AP31-AF31 -> 0 | AU31: 32.78 | AV31: 20.78
A32: Lievegem | B32: Oost-Vlaanderen | C32: 44085 | D32: 26657 | E32: 26979 | F32: 27225 | G32: 27350 | H32: 9 | I32: 0 | J32: 0.33762239 | K32: 10 | L32: 1 | M32: 0.37513599 | N32: 10 | O32: 4 | P32: 0.37065866 | Q32: 0.14826346 | R32: 1 | S32: 0.033036272 | T32: 0 | U32: -0.0044773264 | V32: 9 | W32: 0.33359279 | X32: 8 | Y32: 4 | Z32: 0.29652693 | AA32: 0.14826346 | AB32: 8 | AC32: 4 | AD32: 0.29384757 | AE32: 0.14692378 | AF32: 11 | AG32: 6 | AH32: 0.4040404 | AI32: 0.22038567 | AJ32: =BattMobility!D153+cambio!D153+Claus2you!D153+CoopStroom!D153+Cozywheels!D153+Dégage!D153+Flexigo!D153+Klimaan!D153+Moovee!D153+Poppy!D153+'Mobilize Share'!D153+Stapp.in!D153 -> 13 | AK32: =BattMobility!E153+cambio!E153+Claus2you!E153+CoopStroom!E153+Cozywheels!E153+Dégage!E153+Flexigo!E153+Klimaan!E153+Moovee!E153+Poppy!E153+'Mobilize Share'!E153+Stapp.in!E153 -> 6 | AL32: =AJ32/G32*1000 -> 0.47531993 | AM32: =AK32/G32*1000 -> 0.21937843 | AN32: =AJ32-AB32 -> 5 | AO32: =AN32/AB32 -> 0.625 | AP32: =BattMobility!F153+cambio!F153+Claus2you!F153+CoopStroom!F153+Cozywheels!F153+Dégage!F153+Flexigo!F153+Klimaan!F153+Moovee!F153+Poppy!F153+'Mobilize Share'!F153+Stapp.in!F153 -> 12 | AQ32: =BattMobility!G153+cambio!G153+Claus2you!G153+CoopStroom!G153+Cozywheels!G153+Dégage!G153+Flexigo!G153+Klimaan!G153+Moovee!G153+Poppy!G153+'Mobilize Share'!G153+Stapp.in!G153 -> 6 | AR32: =AP32/G32*1000 -> 0.43875686 | AS32: =AQ32/G32*1000 -> 0.21937843 | AT32: =AP32-AF32 -> 1 | AU32: 54.45 | AV32: 43.45
A33: Herentals | B33: Antwerpen | C33: 13011 | D33: 28455 | E33: 28575 | F33: 28865 | G33: 29001 | H33: 4 | I33: 0 | J33: 0.14057283 | K33: 2 | L33: 0 | M33: 0.070286417 | N33: 7 | O33: 4 | P33: 0.24496938 | Q33: 0.1399825 | R33: 3 | S33: 0.10439654 | T33: 5 | U33: 0.17468296 | V33: 3 | W33: 0.10498688 | X33: 7 | Y33: 4 | Z33: 0.24496938 | AA33: 0.1399825 | AB33: 6 | AC33: 4 | AD33: 0.2078642 | AE33: 0.13857613 | AF33: 8 | AG33: 5 | AH33: 0.27715226 | AI33: 0.17322016 | AJ33: =BattMobility!D93+cambio!D93+Claus2you!D93+CoopStroom!D93+Cozywheels!D93+Dégage!D93+Flexigo!D93+Klimaan!D93+Moovee!D93+Poppy!D93+'Mobilize Share'!D93+Stapp.in!D93 -> 10 | AK33: =BattMobility!E93+cambio!E93+Claus2you!E93+CoopStroom!E93+Cozywheels!E93+Dégage!E93+Flexigo!E93+Klimaan!E93+Moovee!E93+Poppy!E93+'Mobilize Share'!E93+Stapp.in!E93 -> 6 | AL33: =AJ33/G33*1000 -> 0.3448157 | AM33: =AK33/G33*1000 -> 0.20688942 | AN33: =AJ33-AB33 -> 4 | AO33: =AN33/AB33 -> 0.66666667 | AP33: =BattMobility!F93+cambio!F93+Claus2you!F93+CoopStroom!F93+Cozywheels!F93+Dégage!F93+Flexigo!F93+Klimaan!F93+Moovee!F93+Poppy!F93+'Mobilize Share'!F93+Stapp.in!F93 -> 12 | AQ33: =BattMobility!G93+cambio!G93+Claus2you!G93+CoopStroom!G93+Cozywheels!G93+Dégage!G93+Flexigo!G93+Klimaan!G93+Moovee!G93+Poppy!G93+'Mobilize Share'!G93+Stapp.in!G93 -> 7 | AR33: =AP33/G33*1000 -> 0.41377884 | AS33: =AQ33/G33*1000 -> 0.24137099 | AT33: =AP33-AF33 -> 4 | AU33: 57.73 | AV33: 49.73
A34: Aarschot | B34: Vlaams-Brabant | C34: 24001 | D34: 30594 | E34: 30854 | F34: 31138 | G34: 31514 | H34: 3 | I34: 0 | J34: 0.098058443 | K34: 8 | L34: 0 | M34: 0.26148918 | N34: 6 | O34: 6 | P34: 0.19446425 | Q34: 0.19446425 | R34: 3 | S34: 0.096405808 | T34: -2 | U34: -0.06702493 | V34: 0 | W34: 0 | X34: 8 | Y34: 7 | Z34: 0.25928567 | AA34: 0.22687496 | AB34: 7 | AC34: 6 | AD34: 0.2248057 | AE34: 0.1926906 | AF34: 10 | AG34: 8 | AH34: 0.32115101 | AI34: 0.2569208 | AJ34: =BattMobility!D4+cambio!D4+Claus2you!D4+CoopStroom!D4+Cozywheels!D4+Dégage!D4+Flexigo!D4+Klimaan!D4+Moovee!D4+Poppy!D4+'Mobilize Share'!D4+Stapp.in!D4 -> 11 | AK34: =BattMobility!E4+cambio!E4+Claus2you!E4+CoopStroom!E4+Cozywheels!E4+Dégage!E4+Flexigo!E4+Klimaan!E4+Moovee!E4+Poppy!E4+'Mobilize Share'!E4+Stapp.in!E4 -> 8 | AL34: =AJ34/G34*1000 -> 0.34905122 | AM34: =AK34/G34*1000 -> 0.25385543 | AN34: =AJ34-AB34 -> 4 | AO34: =AN34/AB34 -> 0.57142857 | AP34: =BattMobility!F4+cambio!F4+Claus2you!F4+CoopStroom!F4+Cozywheels!F4+Dégage!F4+Flexigo!F4+Klimaan!F4+Moovee!F4+Poppy!F4+'Mobilize Share'!F4+Stapp.in!F4 -> 12 | AQ34: =BattMobility!G4+cambio!G4+Claus2you!G4+CoopStroom!G4+Cozywheels!G4+Dégage!G4+Flexigo!G4+Klimaan!G4+Moovee!G4+Poppy!G4+'Mobilize Share'!G4+Stapp.in!G4 -> 9 | AR34: =AP34/G34*1000 -> 0.38078314 | AS34: =AQ34/G34*1000 -> 0.28558736 | AT34: =AP34-AF34 -> 2 | AU34: 62.276 | AV34: 52.276
A35: Dilbeek | B35: Vlaams-Brabant | C35: 23016 | D35: 44095 | E35: 44650 | F35: 44878 | G35: 45069 | H35: 1 | I35: 0 | J35: 0.022678308 | K35: 0 | L35: 0 | M35: 0 | N35: 1 | O35: 1 | P35: 0.022396417 | Q35: 0.022396417 | R35: 0 | S35: -0.00028189162 | T35: 1 | U35: 0.022396417 | V35: 1 | W35: 0.022396417 | X35: 4 | Y35: 4 | Z35: 0.089585666 | AA35: 0.089585666 | AB35: 6 | AC35: 6 | AD35: 0.1336958 | AE35: 0.1336958 | AF35: 9 | AG35: 8 | AH35: 0.2005437 | AI35: 0.17826106 | AJ35: =BattMobility!D60+cambio!D60+Claus2you!D60+CoopStroom!D60+Cozywheels!D60+Dégage!D60+Flexigo!D60+Klimaan!D60+Moovee!D60+Poppy!D60+'Mobilize Share'!D60+Stapp.in!D60 -> 13 | AK35: =BattMobility!E60+cambio!E60+Claus2you!E60+CoopStroom!E60+Cozywheels!E60+Dégage!E60+Flexigo!E60+Klimaan!E60+Moovee!E60+Poppy!E60+'Mobilize Share'!E60+Stapp.in!E60 -> 12 | AL35: =AJ35/G35*1000 -> 0.2884466 | AM35: =AK35/G35*1000 -> 0.2662584 | AN35: =AJ35-AB35 -> 7 | AO35: =AN35/AB35 -> 1.1666667 | AP35: =BattMobility!F60+cambio!F60+Claus2you!F60+CoopStroom!F60+Cozywheels!F60+Dégage!F60+Flexigo!F60+Klimaan!F60+Moovee!F60+Poppy!F60+'Mobilize Share'!F60+Stapp.in!F60 -> 12 | AQ35: =BattMobility!G60+cambio!G60+Claus2you!G60+CoopStroom!G60+Cozywheels!G60+Dégage!G60+Flexigo!G60+Klimaan!G60+Moovee!G60+Poppy!G60+'Mobilize Share'!G60+Stapp.in!G60 -> 12 | AR35: =AP35/G35*1000 -> 0.2662584 | AS35: =AQ35/G35*1000 -> 0.2662584 | AT35: =AP35-AF35 -> 3 | AU35: 89.756 | AV35: 80.756
A36: Holsbeek | B36: Vlaams-Brabant | C36: 24043 | D36: 10110 | E36: 10158 | F36: 10207 | G36: 10234 | H36: 3 | I36: 0 | J36: 0.29673591 | K36: 3 | L36: 0 | M36: 0.29673591 | N36: 2 | O36: 1 | P36: 0.19688915 | Q36: 0.098444576 | R36: -1 | S36: -0.099846754 | T36: -1 | U36: -0.099846754 | V36: 2 | W36: 0.19688915 | X36: 2 | Y36: 1 | Z36: 0.19688915 | AA36: 0.098444576 | AB36: 5 | AC36: 1 | AD36: 0.4898599 | AE36: 0.09797198 | AF36: 11 | AG36: 5 | AH36: 1.0776918 | AI36: 0.4898599 | AJ36: =BattMobility!D103+cambio!D103+Claus2you!D103+CoopStroom!D103+Cozywheels!D103+Dégage!D103+Flexigo!D103+Klimaan!D103+Moovee!D103+Poppy!D103+'Mobilize Share'!D103+Stapp.in!D103 -> 11 | AK36: =BattMobility!E103+cambio!E103+Claus2you!E103+CoopStroom!E103+Cozywheels!E103+Dégage!E103+Flexigo!E103+Klimaan!E103+Moovee!E103+Poppy!E103+'Mobilize Share'!E103+Stapp.in!E103 -> 5 | AL36: =AJ36/G36*1000 -> 1.0748485 | AM36: =AK36/G36*1000 -> 0.48856752 | AN36: =AJ36-AB36 -> 6 | AO36: =AN36/AB36 -> 1.2 | AP36: =BattMobility!F103+cambio!F103+Claus2you!F103+CoopStroom!F103+Cozywheels!F103+Dégage!F103+Flexigo!F103+Klimaan!F103+Moovee!F103+Poppy!F103+'Mobilize Share'!F103+Stapp.in!F103 -> 11 | AQ36: =BattMobility!G103+cambio!G103+Claus2you!G103+CoopStroom!G103+Cozywheels!G103+Dégage!G103+Flexigo!G103+Klimaan!G103+Moovee!G103+Poppy!G103+'Mobilize Share'!G103+Stapp.in!G103 -> 5 | AR36: =AP36/G36*1000 -> 1.0748485 | AS36: =AQ36/G36*1000 -> 0.48856752 | AT36: =AP36-AF36 -> 0 | AU36: 20.414 | AV36: 9.414
A37: Tervuren | B37: Vlaams-Brabant | C37: 24104 | D37: 22852 | E37: 23101 | F37: 23077 | G37: 23246 | H37: 3 | I37: 0 | J37: 0.13127954 | K37: 5 | L37: 0 | M37: 0.21879923 | N37: 6 | O37: 2 | P37: 0.25972902 | Q37: 0.086576339 | R37: 3 | S37: 0.12844948 | T37: 1 | U37: 0.040929786 | V37: 1 | W37: 0.043288169 | X37: 8 | Y37: 3 | Z37: 0.34630535 | AA37: 0.12986451 | AB37: 7 | AC37: 2 | AD37: 0.30333232 | AE37: 0.086666378 | AF37: 9 | AG37: 3 | AH37: 0.3899987 | AI37: 0.12999957 | AJ37: =BattMobility!D239+cambio!D239+Claus2you!D239+CoopStroom!D239+Cozywheels!D239+Dégage!D239+Flexigo!D239+Klimaan!D239+Moovee!D239+Poppy!D239+'Mobilize Share'!D239+Stapp.in!D239 -> 9 | AK37: =BattMobility!E239+cambio!E239+Claus2you!E239+CoopStroom!E239+Cozywheels!E239+Dégage!E239+Flexigo!E239+Klimaan!E239+Moovee!E239+Poppy!E239+'Mobilize Share'!E239+Stapp.in!E239 -> 3 | AL37: =AJ37/G37*1000 -> 0.38716338 | AM37: =AK37/G37*1000 -> 0.12905446 | AN37: =AJ37-AB37 -> 2 | AO37: =AN37/AB37 -> 0.28571429 | AP37: =BattMobility!F239+cambio!F239+Claus2you!F239+CoopStroom!F239+Cozywheels!F239+Dégage!F239+Flexigo!F239+Klimaan!F239+Moovee!F239+Poppy!F239+'Mobilize Share'!F239+Stapp.in!F239 -> 11 | AQ37: =BattMobility!G239+cambio!G239+Claus2you!G239+CoopStroom!G239+Cozywheels!G239+Dégage!G239+Flexigo!G239+Klimaan!G239+Moovee!G239+Poppy!G239+'Mobilize Share'!G239+Stapp.in!G239 -> 5 | AR37: =AP37/G37*1000 -> 0.47319969 | AS37: =AQ37/G37*1000 -> 0.21509077 | AT37: =AP37-AF37 -> 2 | AU37: 46.154 | AV37: 37.154
A38: Diest | B38: Vlaams-Brabant | C38: 24020 | D38: 24516 | E38: 24677 | F38: 24971 | G38: 25141 | H38: 5 | I38: 0 | J38: 0.20394844 | K38: 5 | L38: 0 | M38: 0.20394844 | N38: 4 | O38: 0 | P38: 0.16209426 | Q38: 0 | R38: -1 | S38: -0.041854184 | T38: -1 | U38: -0.041854184 | V38: 0 | W38: 0 | X38: 6 | Y38: 0 | Z38: 0.24314139 | AA38: 0 | AB38: 8 | AC38: 0 | AD38: 0.32037163 | AE38: 0 | AF38: 10 | AG38: 2 | AH38: 0.40046454 | AI38: 0.080092908 | AJ38: =BattMobility!D58+cambio!D58+Claus2you!D58+CoopStroom!D58+Cozywheels!D58+Dégage!D58+Flexigo!D58+Klimaan!D58+Moovee!D58+Poppy!D58+'Mobilize Share'!D58+Stapp.in!D58 -> 12 | AK38: =BattMobility!E58+cambio!E58+Claus2you!E58+CoopStroom!E58+Cozywheels!E58+Dégage!E58+Flexigo!E58+Klimaan!E58+Moovee!E58+Poppy!E58+'Mobilize Share'!E58+Stapp.in!E58 -> 4 | AL38: =AJ38/G38*1000 -> 0.47730798 | AM38: =AK38/G38*1000 -> 0.15910266 | AN38: =AJ38-AB38 -> 4 | AO38: =AN38/AB38 -> 0.5 | AP38: =BattMobility!F58+cambio!F58+Claus2you!F58+CoopStroom!F58+Cozywheels!F58+Dégage!F58+Flexigo!F58+Klimaan!F58+Moovee!F58+Poppy!F58+'Mobilize Share'!F58+Stapp.in!F58 -> 11 | AQ38: =BattMobility!G58+cambio!G58+Claus2you!G58+CoopStroom!G58+Cozywheels!G58+Dégage!G58+Flexigo!G58+Klimaan!G58+Moovee!G58+Poppy!G58+'Mobilize Share'!G58+Stapp.in!G58 -> 2 | AR38: =AP38/G38*1000 -> 0.43753232 | AS38: =AQ38/G38*1000 -> 0.07955133 | AT38: =AP38-AF38 -> 1 | AU38: 49.942 | AV38: 39.942
A39: Wetteren | B39: Oost-Vlaanderen | C39: 42025 | D39: 26444 | E39: 26748 | F39: 26960 | G39: 26926 | H39: 7 | I39: 1 | J39: 0.26471033 | K39: 7 | L39: 1 | M39: 0.26471033 | N39: 8 | O39: 2 | P39: 0.29908778 | Q39: 0.074771946 | R39: 1 | S39: 0.034377451 | T39: 1 | U39: 0.034377451 | V39: 4 | W39: 0.14954389 | X39: 7 | Y39: 1 | Z39: 0.26170181 | AA39: 0.037385973 | AB39: 6 | AC39: 1 | AD39: 0.22255193 | AE39: 0.037091988 | AF39: 11 | AG39: 4 | AH39: 0.40801187 | AI39: 0.14836795 | AJ39: =BattMobility!D260+cambio!D260+Claus2you!D260+CoopStroom!D260+Cozywheels!D260+Dégage!D260+Flexigo!D260+Klimaan!D260+Moovee!D260+Poppy!D260+'Mobilize Share'!D260+Stapp.in!D260 -> 10 | AK39: =BattMobility!E260+cambio!E260+Claus2you!E260+CoopStroom!E260+Cozywheels!E260+Dégage!E260+Flexigo!E260+Klimaan!E260+Moovee!E260+Poppy!E260+'Mobilize Share'!E260+Stapp.in!E260 -> 3 | AL39: =AJ39/G39*1000 -> 0.37138825 | AM39: =AK39/G39*1000 -> 0.11141647 | AN39: =AJ39-AB39 -> 4 | AO39: =AN39/AB39 -> 0.66666667 | AP39: =BattMobility!F260+cambio!F260+Claus2you!F260+CoopStroom!F260+Cozywheels!F260+Dégage!F260+Flexigo!F260+Klimaan!F260+Moovee!F260+Poppy!F260+'Mobilize Share'!F260+Stapp.in!F260 -> 11 | AQ39: =BattMobility!G260+cambio!G260+Claus2you!G260+CoopStroom!G260+Cozywheels!G260+Dégage!G260+Flexigo!G260+Klimaan!G260+Moovee!G260+Poppy!G260+'Mobilize Share'!G260+Stapp.in!G260 -> 3 | AR39: =AP39/G39*1000 -> 0.40852707 | AS39: =AQ39/G39*1000 -> 0.11141647 | AT39: =AP39-AF39 -> 0 | AU39: 53.92 | AV39: 42.92
A40: Evergem | B40: Oost-Vlaanderen | C40: 44019 | D40: 36087 | E40: 36557 | F40: 36860 | G40: 37254 | H40: 6 | I40: 0 | J40: 0.16626486 | K40: 3 | L40: 0 | M40: 0.08313243 | N40: 3 | O40: 2 | P40: 0.082063627 | Q40: 0.054709084 | R40: -3 | S40: -0.084201233 | T40: 0 | U40: -0.0010688033 | V40: 1 | W40: 0.027354542 | X40: 4 | Y40: 2 | Z40: 0.10941817 | AA40: 0.054709084 | AB40: 5 | AC40: 3 | AD40: 0.1356484 | AE40: 0.08138904 | AF40: 7 | AG40: 5 | AH40: 0.18990776 | AI40: 0.1356484 | AJ40: =BattMobility!D68+cambio!D68+Claus2you!D68+CoopStroom!D68+Cozywheels!D68+Dégage!D68+Flexigo!D68+Klimaan!D68+Moovee!D68+Poppy!D68+'Mobilize Share'!D68+Stapp.in!D68 -> 11 | AK40: =BattMobility!E68+cambio!E68+Claus2you!E68+CoopStroom!E68+Cozywheels!E68+Dégage!E68+Flexigo!E68+Klimaan!E68+Moovee!E68+Poppy!E68+'Mobilize Share'!E68+Stapp.in!E68 -> 9 | AL40: =AJ40/G40*1000 -> 0.29527031 | AM40: =AK40/G40*1000 -> 0.2415848 | AN40: =AJ40-AB40 -> 6 | AO40: =AN40/AB40 -> 1.2 | AP40: =BattMobility!F68+cambio!F68+Claus2you!F68+CoopStroom!F68+Cozywheels!F68+Dégage!F68+Flexigo!F68+Klimaan!F68+Moovee!F68+Poppy!F68+'Mobilize Share'!F68+Stapp.in!F68 -> 11 | AQ40: =BattMobility!G68+cambio!G68+Claus2you!G68+CoopStroom!G68+Cozywheels!G68+Dégage!G68+Flexigo!G68+Klimaan!G68+Moovee!G68+Poppy!G68+'Mobilize Share'!G68+Stapp.in!G68 -> 9 | AR40: =AP40/G40*1000 -> 0.29527031 | AS40: =AQ40/G40*1000 -> 0.2415848 | AT40: =AP40-AF40 -> 4 | AU40: 73.72 | AV40: 66.72
...

Sheet overzicht voor jun 25
